<sdf version='1.6'>
  <world name='default'>
    <light name='sun' type='directional'>
      <cast_shadows>1</cast_shadows>
      <pose frame=''>0 0 10 0 -0 0</pose>
      <diffuse>0.8 0.8 0.8 1</diffuse>
      <specular>0.1 0.1 0.1 1</specular>
      <attenuation>
        <range>1000</range>
        <constant>0.9</constant>
        <linear>0.01</linear>
        <quadratic>0.001</quadratic>
      </attenuation>
      <direction>-0.5 0.5 -1</direction>
    </light>
    <model name='ground_plane'>
      <static>1</static>
      <link name='link'>
        <collision name='collision'>
          <geometry>
            <plane>
              <normal>0 0 1</normal>
              <size>100 100</size>
            </plane>
          </geometry>
          <surface>
            <friction>
              <ode>
                <mu>100</mu>
                <mu2>50</mu2>
              </ode>
              <torsional>
                <ode/>
              </torsional>
            </friction>
            <contact>
              <ode/>
            </contact>
            <bounce/>
          </surface>
          <max_contacts>10</max_contacts>
        </collision>
        <visual name='visual'>
          <cast_shadows>0</cast_shadows>
          <geometry>
            <plane>
              <normal>0 0 1</normal>
              <size>100 100</size>
            </plane>
          </geometry>
          <material>
            <script>
              <uri>file://media/materials/scripts/gazebo.material</uri>
              <name>Gazebo/Grey</name>
            </script>
          </material>
        </visual>
        <self_collide>0</self_collide>
        <kinematic>0</kinematic>
        <gravity>1</gravity>
        <enable_wind>0</enable_wind>
      </link>
    </model>
    <physics name='default_physics' default='0' type='ode'>
      <ode>
        <solver>
          <type>quick</type>
          <iters>10</iters>
          <sor>1.3</sor>
          <use_dynamic_moi_rescaling>0</use_dynamic_moi_rescaling>
        </solver>
        <constraints>
          <cfm>0</cfm>
          <erp>0.2</erp>
          <contact_max_correcting_vel>100</contact_max_correcting_vel>
          <contact_surface_layer>0.001</contact_surface_layer>
        </constraints>
      </ode>
      <max_step_size>0.001</max_step_size>
      <real_time_factor>1</real_time_factor>
      <real_time_update_rate>500</real_time_update_rate>
    </physics>
    <model name='pioneer2dx'>
      <link name='chassis'>
        <pose frame=''>0 0 0.16 0 -0 0</pose>
        <inertial>
          <mass>5.67</mass>
          <inertia>
            <ixx>0.07</ixx>
            <iyy>0.08</iyy>
            <izz>0.1</izz>
            <ixy>0</ixy>
            <ixz>0</ixz>
            <iyz>0</iyz>
          </inertia>
          <pose frame=''>0 0 0 0 -0 0</pose>
        </inertial>
        <collision name='collision'>
          <geometry>
            <box>
              <size>0.445 0.277 0.17</size>
            </box>
          </geometry>
          <max_contacts>10</max_contacts>
          <surface>
            <contact>
              <ode/>
            </contact>
            <bounce/>
            <friction>
              <torsional>
                <ode/>
              </torsional>
              <ode/>
            </friction>
          </surface>
        </collision>
        <collision name='castor_collision'>
          <pose frame=''>-0.2 0 -0.12 0 -0 0</pose>
          <geometry>
            <sphere>
              <radius>0.04</radius>
            </sphere>
          </geometry>
          <surface>
            <friction>
              <ode>
                <mu>0</mu>
                <mu2>0</mu2>
                <slip1>1</slip1>
                <slip2>1</slip2>
              </ode>
              <torsional>
                <ode/>
              </torsional>
            </friction>
            <contact>
              <ode/>
            </contact>
            <bounce/>
          </surface>
          <max_contacts>10</max_contacts>
        </collision>
        <visual name='visual'>
          <pose frame=''>0 0 0.04 0 -0 0</pose>
          <geometry>
            <mesh>
              <uri>model://pioneer2dx/meshes/chassis.dae</uri>
            </mesh>
          </geometry>
        </visual>
        <visual name='castor_visual'>
          <pose frame=''>-0.2 0 -0.12 0 -0 0</pose>
          <geometry>
            <sphere>
              <radius>0.04</radius>
            </sphere>
          </geometry>
          <material>
            <script>
              <uri>file://media/materials/scripts/gazebo.material</uri>
              <name>Gazebo/FlatBlack</name>
            </script>
          </material>
        </visual>
        <self_collide>0</self_collide>
        <enable_wind>0</enable_wind>
        <kinematic>0</kinematic>
      </link>
      <link name='imu'>
        <pose frame=''>0 0 0.17 0 -0 0</pose>
        <inertial>
          <mass>0.1</mass>
          <pose frame=''>0 0 0 0 -0 0</pose>
          <inertia>
            <ixx>1</ixx>
            <ixy>0</ixy>
            <ixz>0</ixz>
            <iyy>1</iyy>
            <iyz>0</iyz>
            <izz>1</izz>
          </inertia>
        </inertial>
        <visual name='visual'>
          <geometry>
            <box>
              <size>0.01 0.01 0.01</size>
            </box>
          </geometry>
        </visual>
        <collision name='collision'>
          <geometry>
            <box>
              <size>0.01 0.01 0.01</size>
            </box>
          </geometry>
          <max_contacts>10</max_contacts>
          <surface>
            <contact>
              <ode/>
            </contact>
            <bounce/>
            <friction>
              <torsional>
                <ode/>
              </torsional>
              <ode/>
            </friction>
          </surface>
        </collision>
        <sensor name='imu' type='imu'>
          <imu>
            <angular_velocity>
              <x>
                <noise type='gaussian'>
                  <mean>0</mean>
                  <stddev>0.0002</stddev>
                  <bias_mean>7.5e-06</bias_mean>
                  <bias_stddev>8e-07</bias_stddev>
                </noise>
              </x>
              <y>
                <noise type='gaussian'>
                  <mean>0</mean>
                  <stddev>0.0002</stddev>
                  <bias_mean>7.5e-06</bias_mean>
                  <bias_stddev>8e-07</bias_stddev>
                </noise>
              </y>
              <z>
                <noise type='gaussian'>
                  <mean>0</mean>
                  <stddev>0.0002</stddev>
                  <bias_mean>7.5e-06</bias_mean>
                  <bias_stddev>8e-07</bias_stddev>
                </noise>
              </z>
            </angular_velocity>
            <linear_acceleration>
              <x>
                <noise type='gaussian'>
                  <mean>0</mean>
                  <stddev>0.017</stddev>
                  <bias_mean>0.1</bias_mean>
                  <bias_stddev>0.001</bias_stddev>
                </noise>
              </x>
              <y>
                <noise type='gaussian'>
                  <mean>0</mean>
                  <stddev>0.017</stddev>
                  <bias_mean>0.1</bias_mean>
                  <bias_stddev>0.001</bias_stddev>
                </noise>
              </y>
              <z>
                <noise type='gaussian'>
                  <mean>0</mean>
                  <stddev>0.017</stddev>
                  <bias_mean>0.1</bias_mean>
                  <bias_stddev>0.001</bias_stddev>
                </noise>
              </z>
            </linear_acceleration>
          </imu>
          <always_on>1</always_on>
          <update_rate>100</update_rate>
        </sensor>
        <self_collide>0</self_collide>
        <enable_wind>0</enable_wind>
        <kinematic>0</kinematic>
      </link>
      <link name='right_wheel'>
        <pose frame=''>0.1 -0.17 0.11 -0 1.5707 1.5707</pose>
        <inertial>
          <mass>1.5</mass>
          <inertia>
            <ixx>0.0051</ixx>
            <iyy>0.0051</iyy>
            <izz>0.009</izz>
            <ixy>0</ixy>
            <ixz>0</ixz>
            <iyz>0</iyz>
          </inertia>
          <pose frame=''>0 0 0 0 -0 0</pose>
        </inertial>
        <collision name='collision'>
          <geometry>
            <cylinder>
              <radius>0.11</radius>
              <length>0.05</length>
            </cylinder>
          </geometry>
          <surface>
            <friction>
              <ode>
                <mu>100000</mu>
                <mu2>100000</mu2>
                <slip1>0</slip1>
                <slip2>0</slip2>
              </ode>
              <torsional>
                <ode/>
              </torsional>
            </friction>
            <contact>
              <ode/>
            </contact>
            <bounce/>
          </surface>
          <max_contacts>10</max_contacts>
        </collision>
        <visual name='visual'>
          <geometry>
            <cylinder>
              <radius>0.11</radius>
              <length>0.05</length>
            </cylinder>
          </geometry>
          <material>
            <script>
              <uri>file://media/materials/scripts/gazebo.material</uri>
              <name>Gazebo/FlatBlack</name>
            </script>
          </material>
        </visual>
        <self_collide>0</self_collide>
        <enable_wind>0</enable_wind>
        <kinematic>0</kinematic>
      </link>
      <link name='left_wheel'>
        <pose frame=''>0.1 0.17 0.11 -0 1.5707 1.5707</pose>
        <inertial>
          <mass>1.5</mass>
          <inertia>
            <ixx>0.0051</ixx>
            <iyy>0.0051</iyy>
            <izz>0.009</izz>
            <ixy>0</ixy>
            <ixz>0</ixz>
            <iyz>0</iyz>
          </inertia>
          <pose frame=''>0 0 0 0 -0 0</pose>
        </inertial>
        <collision name='collision'>
          <geometry>
            <cylinder>
              <radius>0.11</radius>
              <length>0.05</length>
            </cylinder>
          </geometry>
          <surface>
            <friction>
              <ode>
                <mu>100000</mu>
                <mu2>100000</mu2>
                <slip1>0</slip1>
                <slip2>0</slip2>
              </ode>
              <torsional>
                <ode/>
              </torsional>
            </friction>
            <contact>
              <ode/>
            </contact>
            <bounce/>
          </surface>
          <max_contacts>10</max_contacts>
        </collision>
        <visual name='visual'>
          <geometry>
            <cylinder>
              <radius>0.11</radius>
              <length>0.05</length>
            </cylinder>
          </geometry>
          <material>
            <script>
              <uri>file://media/materials/scripts/gazebo.material</uri>
              <name>Gazebo/FlatBlack</name>
            </script>
          </material>
        </visual>
        <self_collide>0</self_collide>
        <enable_wind>0</enable_wind>
        <kinematic>0</kinematic>
      </link>
      <link name='ofs'>
        <pose frame=''>-0.1 0.05 0.17 0 -0 0</pose>
        <inertial>
          <mass>0.1</mass>
          <pose frame=''>0 0 0 0 -0 0</pose>
          <inertia>
            <ixx>1</ixx>
            <ixy>0</ixy>
            <ixz>0</ixz>
            <iyy>1</iyy>
            <iyz>0</iyz>
            <izz>1</izz>
          </inertia>
        </inertial>
        <visual name='visual'>
          <geometry>
            <box>
              <size>0.01 0.01 0.01</size>
            </box>
          </geometry>
        </visual>
        <collision name='collision'>
          <geometry>
            <box>
              <size>0.01 0.01 0.01</size>
            </box>
          </geometry>
          <max_contacts>10</max_contacts>
          <surface>
            <contact>
              <ode/>
            </contact>
            <bounce/>
            <friction>
              <torsional>
                <ode/>
              </torsional>
              <ode/>
            </friction>
          </surface>
        </collision>
        <self_collide>0</self_collide>
        <enable_wind>0</enable_wind>
        <kinematic>0</kinematic>
      </link>
      <joint name='left_wheel_hinge' type='revolute'>
        <pose frame=''>0 0 -0.03 0 -0 0</pose>
        <child>left_wheel</child>
        <parent>chassis</parent>
        <axis>
          <xyz>0 1 0</xyz>
          <use_parent_model_frame>1</use_parent_model_frame>
          <limit>
            <lower>-1e+16</lower>
            <upper>1e+16</upper>
          </limit>
          <dynamics>
            <spring_reference>0</spring_reference>
            <spring_stiffness>0</spring_stiffness>
          </dynamics>
        </axis>
      </joint>
      <joint name='right_wheel_hinge' type='revolute'>
        <pose frame=''>0 0 0.03 0 -0 0</pose>
        <child>right_wheel</child>
        <parent>chassis</parent>
        <axis>
          <xyz>0 1 0</xyz>
          <use_parent_model_frame>1</use_parent_model_frame>
          <limit>
            <lower>-1e+16</lower>
            <upper>1e+16</upper>
          </limit>
          <dynamics>
            <spring_reference>0</spring_reference>
            <spring_stiffness>0</spring_stiffness>
          </dynamics>
        </axis>
      </joint>
      <joint name='IMU_hinge' type='revolute'>
        <pose frame=''>0 0 0 0 -0 0</pose>
        <child>imu</child>
        <parent>chassis</parent>
        <axis>
          <xyz>0 0 0</xyz>
          <use_parent_model_frame>1</use_parent_model_frame>
          <limit>
            <lower>-1e+16</lower>
            <upper>1e+16</upper>
          </limit>
          <dynamics>
            <spring_reference>0</spring_reference>
            <spring_stiffness>0</spring_stiffness>
          </dynamics>
        </axis>
      </joint>
      <joint name='OFS_hinge' type='revolute'>
        <pose frame=''>0 0 0 0 -0 0</pose>
        <child>ofs</child>
        <parent>chassis</parent>
        <axis>
          <xyz>0 0 0</xyz>
          <use_parent_model_frame>1</use_parent_model_frame>
          <limit>
            <lower>-1e+16</lower>
            <upper>1e+16</upper>
          </limit>
          <dynamics>
            <spring_reference>0</spring_reference>
            <spring_stiffness>0</spring_stiffness>
          </dynamics>
        </axis>
      </joint>
    </model>
    <plugin name='GazeboPlugin' filename='lib/libGazeboCoSimPlugin.so'>
      <portNumber>14581</portNumber>
    </plugin>
    <gravity>0 0 -9.8</gravity>
    <magnetic_field>6e-06 2.3e-05 -4.2e-05</magnetic_field>
    <atmosphere type='adiabatic'/>
    <scene>
      <ambient>0.4 0.4 0.4 1</ambient>
      <background>0.7 0.7 0.7 1</background>
      <shadows>1</shadows>
    </scene>
    <wind/>
    <spherical_coordinates>
      <surface_model>EARTH_WGS84</surface_model>
      <latitude_deg>0</latitude_deg>
      <longitude_deg>0</longitude_deg>
      <elevation>0</elevation>
      <heading_deg>0</heading_deg>
    </spherical_coordinates>
    <model name='Untitled'>
      <model name='Untitled'>
        <model name='Untitled'>
          <model name='block_car'>
            <link name='link_0'>
              <inertial>
                <mass>94.4748</mass>
                <inertia>
                  <ixx>710.568</ixx>
                  <ixy>0</ixy>
                  <ixz>0</ixz>
                  <iyy>15.7458</iyy>
                  <iyz>0</iyz>
                  <izz>710.568</izz>
                </inertia>
                <pose frame=''>0 0 0 0 -0 0</pose>
              </inertial>
              <pose frame=''>0 0 0 0 -0 0</pose>
              <gravity>1</gravity>
              <self_collide>0</self_collide>
              <kinematic>0</kinematic>
              <enable_wind>0</enable_wind>
              <visual name='visual'>
                <pose frame=''>0 0 0 0 -0 0</pose>
                <geometry>
                  <box>
                    <size>1 9.44748 1</size>
                  </box>
                </geometry>
                <material>
                  <lighting>1</lighting>
                  <script>
                    <uri>file://media/materials/scripts/gazebo.material</uri>
                    <name>Gazebo/Grey</name>
                  </script>
                  <shader type='pixel'>
                    <normal_map>__default__</normal_map>
                  </shader>
                </material>
                <transparency>0</transparency>
                <cast_shadows>1</cast_shadows>
              </visual>
              <collision name='collision'>
                <laser_retro>0</laser_retro>
                <max_contacts>10</max_contacts>
                <pose frame=''>0 0 0 0 -0 0</pose>
                <geometry>
                  <box>
                    <size>1 9.44748 1</size>
                  </box>
                </geometry>
                <surface>
                  <friction>
                    <ode>
                      <mu>1</mu>
                      <mu2>1</mu2>
                      <fdir1>0 0 0</fdir1>
                      <slip1>0</slip1>
                      <slip2>0</slip2>
                    </ode>
                    <torsional>
                      <coefficient>1</coefficient>
                      <patch_radius>0</patch_radius>
                      <surface_radius>0</surface_radius>
                      <use_patch_radius>1</use_patch_radius>
                      <ode>
                        <slip>0</slip>
                      </ode>
                    </torsional>
                  </friction>
                  <bounce>
                    <restitution_coefficient>0</restitution_coefficient>
                    <threshold>1e+06</threshold>
                  </bounce>
                  <contact>
                    <collide_without_contact>0</collide_without_contact>
                    <collide_without_contact_bitmask>1</collide_without_contact_bitmask>
                    <collide_bitmask>1</collide_bitmask>
                    <ode>
                      <soft_cfm>0</soft_cfm>
                      <soft_erp>0.2</soft_erp>
                      <kp>1e+13</kp>
                      <kd>1</kd>
                      <max_vel>0.01</max_vel>
                      <min_depth>0</min_depth>
                    </ode>
                    <bullet>
                      <split_impulse>1</split_impulse>
                      <split_impulse_penetration_threshold>-0.01</split_impulse_penetration_threshold>
                      <soft_cfm>0</soft_cfm>
                      <soft_erp>0.2</soft_erp>
                      <kp>1e+13</kp>
                      <kd>1</kd>
                    </bullet>
                  </contact>
                </surface>
              </collision>
            </link>
            <static>0</static>
            <allow_auto_disable>1</allow_auto_disable>
            <pose frame=''>-0 -4e-06 0 0 -0 0</pose>
          </model>
          <static>0</static>
          <allow_auto_disable>1</allow_auto_disable>
          <pose frame=''>-5e-06 -2e-06 0 0 -0 0</pose>
        </model>
        <static>0</static>
        <allow_auto_disable>1</allow_auto_disable>
        <pose frame=''>-1e-06 -4e-06 0 0 -0 0</pose>
      </model>
      <static>0</static>
      <allow_auto_disable>1</allow_auto_disable>
      <pose frame=''>2.44423 4.38141 0 0 -0 0</pose>
    </model>
    <state world_name='default'>
      <sim_time>0 0</sim_time>
      <real_time>0 0</real_time>
      <wall_time>1693290578 24859231</wall_time>
      <iterations>0</iterations>
      <model name='Untitled'>
        <pose frame=''>3.85523 4.38141 0.477044 0 -0 0</pose>
        <scale>1 1 1</scale>
        <model name='Untitled'>
          <pose frame=''>3.85523 4.38141 0.477044 0 -0 0</pose>
          <scale>1 1 1</scale>
          <model name='Untitled'>
            <pose frame=''>3.85523 4.3814 0.477044 0 -0 0</pose>
            <scale>1 1 1</scale>
            <model name='block_car'>
              <pose frame=''>3.85523 4.3814 0.477044 0 -0 0</pose>
              <scale>1 1 1</scale>
              <link name='link_0'>
                <pose frame=''>3.85523 4.3814 0.477044 0 -0 0</pose>
                <velocity>0 0 0 0 -0 0</velocity>
                <acceleration>2.44579 -0.178199 -9.00734 2.78073 -0.685343 -2.00948</acceleration>
                <wrench>231.066 -16.8353 -850.967 0 -0 0</wrench>
              </link>
            </model>
          </model>
        </model>
      </model>
      <model name='ground_plane'>
        <pose frame=''>0 0 0 0 -0 0</pose>
        <scale>1 1 1</scale>
        <link name='link'>
          <pose frame=''>0 0 0 0 -0 0</pose>
          <velocity>0 0 0 0 -0 0</velocity>
          <acceleration>0 0 0 0 -0 0</acceleration>
          <wrench>0 0 0 0 -0 0</wrench>
        </link>
      </model>
      <model name='pioneer2dx'>
        <pose frame=''>0 0 0 0 -0 0</pose>
        <scale>1 1 1</scale>
        <link name='chassis'>
          <pose frame=''>0 0 0.16 0 -0 0</pose>
          <velocity>0 0 0 0 -0 0</velocity>
          <acceleration>6.45005 -3.75581 -3.14847 0.710965 1.10891 -2.26546</acceleration>
          <wrench>36.5718 -21.2954 -17.8518 0 -0 0</wrench>
        </link>
        <link name='imu'>
          <pose frame=''>0 0 0.17 0 -0 0</pose>
          <velocity>0 0 0 0 -0 0</velocity>
          <acceleration>6.56891 -2.45834 -4.00498 0.016677 0.606916 0.322563</acceleration>
          <wrench>0.656891 -0.245834 -0.400498 0 -0 0</wrench>
        </link>
        <link name='left_wheel'>
          <pose frame=''>0.1 0.17 0.11 -0 1.5707 1.5707</pose>
          <velocity>0 0 0 0 -0 0</velocity>
          <acceleration>0.375253 1.35325 -2.72115 -0.124496 0.240073 -2.17752</acceleration>
          <wrench>0.56288 2.02987 -4.08173 0 -0 0</wrench>
        </link>
        <link name='ofs'>
          <pose frame=''>-0.1 0.05 0.17 0 -0 0</pose>
          <velocity>0 0 0 0 -0 0</velocity>
          <acceleration>6.23235 -2.76026 -3.96733 -3.11685 -1.18723 2.44662</acceleration>
          <wrench>0.623235 -0.276026 -0.396733 0 -0 0</wrench>
        </link>
        <link name='right_wheel'>
          <pose frame=''>0.1 -0.17 0.11 -0 1.5707 1.5707</pose>
          <velocity>0 0 0 0 -0 0</velocity>
          <acceleration>8.62759 1.4748 -11.6498 1.67004 -0.003757 0.952684</acceleration>
          <wrench>12.9414 2.2122 -17.4747 0 -0 0</wrench>
        </link>
      </model>
      <light name='sun'>
        <pose frame=''>0 0 10 0 -0 0</pose>
      </light>
    </state>
    <gui fullscreen='0'>
      <camera name='user_camera'>
        <pose frame=''>0.685745 -6.12451 1.20722 0 0.126778 1.39682</pose>
        <view_controller>orbit</view_controller>
        <projection_type>perspective</projection_type>
      </camera>
    </gui>
  </world>
</sdf>
